<?xml version="1.0"?>
<robot xmlns:xacro="http://www.ros.org/wiki/xacro" name="waver">

    <xacro:macro name="wheel" params="name xyz rpy">
        <link name="${name}">
            <visual>
                <geometry>
                    <cylinder length="0.05" radius="0.1" />
                </geometry>
            </visual>
            <collision>
                <geometry>
                    <cylinder length="0.05" radius="0.1" />
                </geometry>
            </collision>
            <inertial>
                <mass value="0.1" />
                <origin xyz="0 0 0" rpy="0 0 0" />
                <inertia ixx="0.001" ixy="0.0" ixz="0.0" iyy="0.001" iyz="0.0" izz="0.001" />
            </inertial>
        </link>
        <joint name="${name}_joint" type="continuous">
            <parent link="base_link" />
            <child link="${name}" />
            <origin xyz="${xyz}" rpy="${rpy}" />
            <axis xyz="0 0 1" />
        </joint>
    </xacro:macro>

</robot>
