<?xml version="1.0"?>
<robot xmlns:xacro="http://www.ros.org/wiki/xacro" name="waver">

    <xacro:macro name="wheel" params="prefix suffix xyz rpy">
        <link name="${prefix}_${suffix}_link">
            <visual>
                <geometry>
                    <mesh filename="package://waver_description/meshes/wheel_husky.stl"
                        scale="1 1 1" />
                </geometry>
                <material name="black">
                    <color rgba="0 0 0 1" />
                </material>
            </visual>
            <collision>
                <geometry>
                    <cylinder length="0.1" radius="0.1" />
                </geometry>
            </collision>
            <inertial>
                <mass value="0.1" />
                <origin xyz="0 0 0" rpy="0 0 0" />
                <inertia ixx="0.001" ixy="0.0" ixz="0.0" iyy="0.001" iyz="0.0" izz="0.001" />
            </inertial>
        </link>

        <joint name="${prefix}_${suffix}_joint" type="continuous">
            <parent link="base_link" />
            <child link="${prefix}_${suffix}_link" />
            <origin xyz="${xyz}" rpy="${rpy}" />
            <axis xyz="0 0 1" />
        </joint>

        <transmission name="${prefix}_${suffix}_trans">
            <type>transmission_interface/SimpleTransmission</type>
            <actuator name="${prefix}_${suffix}_motor">
                <mechanicalReduction>1</mechanicalReduction>
            </actuator>
            <joint name="${prefix}_${suffix}_joint">
                <hardwareInterface>hardware_interface/VelocityJointInterface</hardwareInterface>
            </joint>
        </transmission>

        <gazebo reference="${prefix}_${suffix}">
            <mu1 value="200.0" />
            <mu2 value="100.0" />
            <kp value="10000000.0" />
            <kd value="1.0" />
            <material>Gazebo/Grey</material>
        </gazebo>

    </xacro:macro>

</robot>
